Traceback (most recent call last):
  File "/usr/local/lib/python3.11/site-packages/jupyter_cache/executors/utils.py", line 58, in single_nb_execution
    executenb(
  File "/usr/local/lib/python3.11/site-packages/nbclient/client.py", line 1305, in execute
    return NotebookClient(nb=nb, resources=resources, km=km, **kwargs).execute()
           ^^^^^^^^^^^^^^^^^^^^^^^^^^^^^^^^^^^^^^^^^^^^^^^^^^^^^^^^^^^^^^^^^^^^^
  File "/usr/local/lib/python3.11/site-packages/jupyter_core/utils/__init__.py", line 166, in wrapped
    return loop.run_until_complete(inner)
           ^^^^^^^^^^^^^^^^^^^^^^^^^^^^^^
  File "/usr/local/Cellar/python@3.11/3.11.4/Frameworks/Python.framework/Versions/3.11/lib/python3.11/asyncio/base_events.py", line 653, in run_until_complete
    return future.result()
           ^^^^^^^^^^^^^^^
  File "/usr/local/lib/python3.11/site-packages/nbclient/client.py", line 705, in async_execute
    await self.async_execute_cell(
  File "/usr/local/lib/python3.11/site-packages/nbclient/client.py", line 1058, in async_execute_cell
    await self._check_raise_for_error(cell, cell_index, exec_reply)
  File "/usr/local/lib/python3.11/site-packages/nbclient/client.py", line 914, in _check_raise_for_error
    raise CellExecutionError.from_cell_and_msg(cell, exec_reply_content)
nbclient.exceptions.CellExecutionError: An error occurred while executing the following cell:
------------------
import gif

@gif.frame
def plot_volume(angle):
    fig = plt.figure(figsize = (20, 15))
    
    ax2 = fig.add_subplot(1, 1, 1, projection = '3d')
    angles = np.linspace(0, 360, 20)
    x = np.linspace(-1, 2, 60)
    v = np.linspace(0, 2*angle, 60)

    U, V = np.meshgrid(x, v)
    Y1 = (U**2 + 1)*np.cos(V)
    Z1 = (U**2 + 1)*np.sin(V)
    Y2 = (U + 3)*np.cos(V)
    Z2 = (U + 3)*np.sin(V)
    X = U
    ax2.plot_surface(X, Y1, Z1, alpha = 0.2, color = 'blue', rstride = 6, cstride = 6)
    ax2.plot_surface(X, Y2, Z2, alpha = 0.2, color = 'red', rstride = 6, cstride = 6)
    ax2.set_xlim(-3,3)
    ax2.set_ylim(-5,5)
    ax2.set_zlim(-5,5)
    ax2.view_init(elev = 50, azim = 30*angle)
    ax2.plot_wireframe(X, Y2, Z2)
    ax2.plot_wireframe(X, Y1, Z1, color = 'black')
    ax2._axis3don = False
    
frames = []
for i in np.linspace(0, 2*np.pi, 20):
    frame = plot_volume(i)
    frames.append(frame)
    
gif.save(frames, 'images/vol1.gif', duration = 500)

from IPython.display import Image

Image('images/vol1.gif')
------------------


[0;31m----------------------------------------------------------------------[0m
[0;31mModuleNotFoundError[0m                  Traceback (most recent call last)
Cell [0;32mIn[17], line 1[0m
[0;32m----> 1[0m [38;5;28;01mimport[39;00m [38;5;21;01mgif[39;00m
[1;32m      3[0m [38;5;129m@gif[39m[38;5;241m.[39mframe
[1;32m      4[0m [38;5;28;01mdef[39;00m [38;5;21mplot_volume[39m(angle):
[1;32m      5[0m     fig [38;5;241m=[39m plt[38;5;241m.[39mfigure(figsize [38;5;241m=[39m ([38;5;241m20[39m, [38;5;241m15[39m))

[0;31mModuleNotFoundError[0m: No module named 'gif'

